Failure # 1 (occurred at 2025-05-26_12-23-26)
Traceback (most recent call last):
  File "/home/tristongrayston/anaconda3/envs/cooperative/lib/python3.8/site-packages/ray/tune/trial_runner.py", line 890, in _process_trial
    results = self.trial_executor.fetch_result(trial)
  File "/home/tristongrayston/anaconda3/envs/cooperative/lib/python3.8/site-packages/ray/tune/ray_trial_executor.py", line 788, in fetch_result
    result = ray.get(trial_future[0], timeout=DEFAULT_GET_TIMEOUT)
  File "/home/tristongrayston/anaconda3/envs/cooperative/lib/python3.8/site-packages/ray/_private/client_mode_hook.py", line 105, in wrapper
    return func(*args, **kwargs)
  File "/home/tristongrayston/anaconda3/envs/cooperative/lib/python3.8/site-packages/ray/worker.py", line 1625, in get
    raise value.as_instanceof_cause()
ray.exceptions.RayTaskError(AttributeError): [36mray::MAPPOTrainer.train()[39m (pid=31119, ip=172.19.89.72, repr=MAPPOTrainer)
  File "/home/tristongrayston/anaconda3/envs/cooperative/lib/python3.8/site-packages/ray/rllib/agents/trainer.py", line 679, in train
    raise e
  File "/home/tristongrayston/anaconda3/envs/cooperative/lib/python3.8/site-packages/ray/rllib/agents/trainer.py", line 668, in train
    result = Trainable.train(self)
  File "/home/tristongrayston/anaconda3/envs/cooperative/lib/python3.8/site-packages/ray/tune/trainable.py", line 283, in train
    result = self.step()
  File "/home/tristongrayston/anaconda3/envs/cooperative/lib/python3.8/site-packages/ray/rllib/agents/trainer_template.py", line 206, in step
    step_results = next(self.train_exec_impl)
  File "/home/tristongrayston/anaconda3/envs/cooperative/lib/python3.8/site-packages/ray/util/iter.py", line 756, in __next__
    return next(self.built_iterator)
  File "/home/tristongrayston/anaconda3/envs/cooperative/lib/python3.8/site-packages/ray/util/iter.py", line 783, in apply_foreach
    for item in it:
  File "/home/tristongrayston/anaconda3/envs/cooperative/lib/python3.8/site-packages/ray/util/iter.py", line 783, in apply_foreach
    for item in it:
  File "/home/tristongrayston/anaconda3/envs/cooperative/lib/python3.8/site-packages/ray/util/iter.py", line 843, in apply_filter
    for item in it:
  File "/home/tristongrayston/anaconda3/envs/cooperative/lib/python3.8/site-packages/ray/util/iter.py", line 843, in apply_filter
    for item in it:
  File "/home/tristongrayston/anaconda3/envs/cooperative/lib/python3.8/site-packages/ray/util/iter.py", line 783, in apply_foreach
    for item in it:
  File "/home/tristongrayston/anaconda3/envs/cooperative/lib/python3.8/site-packages/ray/util/iter.py", line 783, in apply_foreach
    for item in it:
  File "/home/tristongrayston/anaconda3/envs/cooperative/lib/python3.8/site-packages/ray/util/iter.py", line 783, in apply_foreach
    for item in it:
  [Previous line repeated 1 more time]
  File "/home/tristongrayston/anaconda3/envs/cooperative/lib/python3.8/site-packages/ray/util/iter.py", line 876, in apply_flatten
    for item in it:
  File "/home/tristongrayston/anaconda3/envs/cooperative/lib/python3.8/site-packages/ray/util/iter.py", line 783, in apply_foreach
    for item in it:
  File "/home/tristongrayston/anaconda3/envs/cooperative/lib/python3.8/site-packages/ray/util/iter.py", line 783, in apply_foreach
    for item in it:
  File "/home/tristongrayston/anaconda3/envs/cooperative/lib/python3.8/site-packages/ray/util/iter.py", line 783, in apply_foreach
    for item in it:
  [Previous line repeated 1 more time]
  File "/home/tristongrayston/anaconda3/envs/cooperative/lib/python3.8/site-packages/ray/util/iter.py", line 471, in base_iterator
    yield ray.get(futures, timeout=timeout)
ray.exceptions.RayTaskError(AttributeError): [36mray::RolloutWorker.par_iter_next()[39m (pid=31119, ip=172.19.89.72, repr=<ray.rllib.evaluation.rollout_worker.modify_class.<locals>.Class object at 0x7f7efd7f7e80>)
  File "/home/tristongrayston/anaconda3/envs/cooperative/lib/python3.8/site-packages/ray/util/iter.py", line 1151, in par_iter_next
    return next(self.local_it)
  File "/home/tristongrayston/anaconda3/envs/cooperative/lib/python3.8/site-packages/ray/rllib/evaluation/rollout_worker.py", line 378, in gen_rollouts
    yield self.sample()
  File "/home/tristongrayston/anaconda3/envs/cooperative/lib/python3.8/site-packages/ray/rllib/evaluation/rollout_worker.py", line 753, in sample
    batches = [self.input_reader.next()]
  File "/home/tristongrayston/anaconda3/envs/cooperative/lib/python3.8/site-packages/ray/rllib/evaluation/sampler.py", line 103, in next
    batches = [self.get_data()]
  File "/home/tristongrayston/anaconda3/envs/cooperative/lib/python3.8/site-packages/ray/rllib/evaluation/sampler.py", line 233, in get_data
    item = next(self._env_runner)
  File "/home/tristongrayston/anaconda3/envs/cooperative/lib/python3.8/site-packages/ray/rllib/evaluation/sampler.py", line 599, in _env_runner
    _process_observations(
  File "/home/tristongrayston/anaconda3/envs/cooperative/lib/python3.8/site-packages/ray/rllib/evaluation/sampler.py", line 822, in _process_observations
    logger.info("Filtered obs: {}".format(summarize(filtered_obs)))
  File "/home/tristongrayston/anaconda3/envs/cooperative/lib/python3.8/site-packages/ray/rllib/utils/debug.py", line 20, in summarize
    return _printer.pformat(_summarize(obj))
  File "/home/tristongrayston/anaconda3/envs/cooperative/lib/python3.8/site-packages/ray/rllib/utils/debug.py", line 39, in _summarize
    elif obj.dtype == np.object or obj.dtype.type is np.str_:
  File "/home/tristongrayston/anaconda3/envs/cooperative/lib/python3.8/site-packages/numpy/__init__.py", line 305, in __getattr__
    raise AttributeError(__former_attrs__[attr])
AttributeError: module 'numpy' has no attribute 'object'.
`np.object` was a deprecated alias for the builtin `object`. To avoid this error in existing code, use `object` by itself. Doing this will not modify any behavior and is safe. 
The aliases was originally deprecated in NumPy 1.20; for more details and guidance see the original release note at:
    https://numpy.org/devdocs/release/1.20.0-notes.html#deprecations

